<?xml version="1.0" ?>
<robot name="simple_four_wheel_robot">

  <!-- Base Link -->
  <link name="base_link">
    <visual>
      <geometry>
        <box size="0.5 0.3 0.1" /> <!-- Dimensions: length, width, height -->
      </geometry>
      <material name="grey">
        <color rgba="0.5 0.5 0.5 1.0" /> <!-- RGBA color for the base -->
      </material>
    </visual>
    <collision>
      <geometry>
        <box size="0.5 0.3 0.1" />
      </geometry>
    </collision>
    <inertial>
      <mass value="5.0" /> <!-- Mass of the base in kg -->
      <inertia ixx="0.1" ixy="0.0" ixz="0.0" iyy="0.1" iyz="0.0" izz="0.1" /> <!-- Inertia values -->
    </inertial>
  </link>

  <!-- Front Left Wheel -->
  <link name="front_left_wheel">
    <visual>
      <geometry>
        <cylinder length="0.05" radius="0.05" /> <!-- Length, radius -->
      </geometry>
      <material name="red">
        <color rgba="1 0.0 0.0 1" /> <!-- Black color for the wheels -->
      </material>
    </visual>
    <collision>
      <geometry>
        <cylinder length="0.05" radius="0.05" />
      </geometry>
      <dynamics friction="5.0" /> <!-- Adjust this value to increase or decrease traction -->
    </collision>
    <inertial>
      <mass value="1.0" />
      <inertia ixx="0.01" ixy="0.0" ixz="0.0" iyy="0.01" iyz="0.0" izz="0.01" />
    </inertial>
  </link>

  <!-- Front Right Wheel -->
  <link name="front_right_wheel">
    <visual>
      <geometry>
        <cylinder length="0.05" radius="0.05" />
      </geometry>
      <material name="red">
        <color rgba="1 0.0 0.0 1.0" />
      </material>
    </visual>
    <collision>
      <geometry>
        <cylinder length="0.05" radius="0.05" />
      </geometry>
      <dynamics friction="5.0" /> <!-- Adjust this value to increase or decrease traction -->
    </collision>
    <inertial>
      <mass value="1.0" />
      <inertia ixx="0.01" ixy="0.0" ixz="0.0" iyy="0.01" iyz="0.0" izz="0.01" />
    </inertial>
  </link>

  <!-- Rear Left Wheel -->
  <link name="rear_left_wheel">
    <visual>
      <geometry>
        <cylinder length="0.05" radius="0.05" />
      </geometry>
      <material name="black">
        <color rgba="0.0 0.0 0.0 1.0" />
      </material>
    </visual>
    <collision>
      <geometry>
        <cylinder length="0.05" radius="0.05" />
      </geometry>
      <dynamics friction="5.0" /> <!-- Adjust this value to increase or decrease traction -->
    </collision>
    <inertial>
      <mass value="1.0" />
      <inertia ixx="0.01" ixy="0.0" ixz="0.0" iyy="0.01" iyz="0.0" izz="0.01" />
    </inertial>
  </link>

  <!-- Rear Right Wheel -->
  <link name="rear_right_wheel">
    <visual>
      <geometry>
        <cylinder length="0.05" radius="0.05" />
      </geometry>
      <material name="black">
        <color rgba="0.0 0.0 0.0 1.0" />
      </material>
    </visual>
    <collision>
      <geometry>
        <cylinder length="0.05" radius="0.05" />
      </geometry>
      <dynamics friction="5.0" /> <!-- Adjust this value to increase or decrease traction -->
    </collision>
    <inertial>
      <mass value="1.0" />
      <inertia ixx="0.01" ixy="0.0" ixz="0.0" iyy="0.01" iyz="0.0" izz="0.01" />
    </inertial>
  </link>

  <!-- Indicates Front of Robot -->
  <link name="front_indicator">
    <visual>
      <origin xyz="0.21 0.0 0.01" rpy="0 0 0"/>
      <geometry>
        <box size='0.1 0.1 0.1' /> <!-- Length, radius -->
      </geometry>
      <material name="red">
        <color rgba="1 0.0 0.0 1" /> <!-- Black color for the wheels -->
      </material>
    </visual>
    <collision>
      <origin xyz="0.21 0.0 0.01" rpy="0 0 0"/>
      <geometry>
        <box size='0.1 0.1 0.1' /> <!-- Length, radius -->
      </geometry>
      <dynamics friction="5.0" /> <!-- Adjust this value to increase or decrease traction -->
    </collision>
    <inertial>
      <mass value="1.0" />
      <inertia ixx="0.01" ixy="0.0" ixz="0.0" iyy="0.01" iyz="0.0" izz="0.01" />
    </inertial>
  </link>

  <!-- Joints -->
  <!-- Front Left Wheel Joint -->
  <joint name="front_left_wheel_joint" type="continuous">
    <parent link="base_link" />
    <child link="front_left_wheel" />
    <origin xyz="0.2 0.15 -0.05" rpy="1.57 0 0" /> <!-- Position of the joint -->
    <axis xyz="0 0 1" /> <!-- Rotation axis of the wheel -->
  </joint>

  <!-- Front Right Wheel Joint -->
  <joint name="front_right_wheel_joint" type="continuous">
    <parent link="base_link" />
    <child link="front_right_wheel" />
    <origin xyz="0.2 -0.15 -0.05" rpy="1.57 0 0" />
    <axis xyz="0 0 1" />
  </joint>

  <!-- Rear Left Wheel Joint -->
  <joint name="rear_left_wheel_joint" type="continuous">
    <parent link="base_link" />
    <child link="rear_left_wheel" />
    <origin xyz="-0.2 0.15 -0.05" rpy="1.57 0 0" />
    <axis xyz="0 0 1" />
  </joint>

  <!-- Rear Right Wheel Joint -->
  <joint name="rear_right_wheel_joint" type="continuous">
    <parent link="base_link" />
    <child link="rear_right_wheel" />
    <origin xyz="-0.2 -0.15 -0.05" rpy="1.57 0 0" />
    <axis xyz="0 0 1" />
  </joint>

  <!-- Front Box Joint -->
  <joint name="front_indicator_joint" type="fixed">
    <parent link="base_link" />
    <child link="front_indicator" />
    <origin xyz="0 0 0" rpy="0 0 0" />
    <axis xyz="0 0 1" />
  </joint>
  
</robot>
